Workbook

Sheet Instructions
A1: Instructions — How to Use This Workbook
A3: 1) Open the Inputs_Calcs tab. In the header, enter: Project Name, Units, blended Electricity $/kWh, and (if applicable) Demand $/kW, Fixed $/mo, Billing Demand (kW), Months/Year.
A4: 2) Interior Lighting: enter areas (ft²) for each common-space row. LPDs auto-fill from Lookups_References. If space planning isn't final, use the 'MFOther (blended preset)' line as a placeholder, then replace with exact spaces later.
A5: 3) Parking Garage: enter garage area and confirm the Parking Garage LPD (defaults to a placeholder). Set hours, days, and a control factor. If the garage is mechanically ventilated, choose Yes and fill the simple fan W/ft², hours, and days.
A6: 4) EV Chargers: set Total Parking Spaces and the % EV Charger Spaces on the Parking Garage section; the EV section pulls those values automatically. Adjust kW/port and hours/day as needed.
A7: 5) Site Lighting: paste Installed Watts per category from NRCC-LTO. Adjust hours/day and control factor to match expected controls (e.g., photocell, motion bi-level).
A8: 6) Pools/Spas (if any): fill pump HP, efficiency, hours/days. Add heater inputs only if present (Electric or Gas).
A9: 7) Review the roll-up at the bottom of Inputs_Calcs and the client-facing Report_Client tab. Print or export Report_Client.
A10: 8) Lookups_References: holds the LPD table, rate shells, and citations. Update rates (blended $/kWh, demand $/kW, fixed $/mo) as needed and record the source & effective date.

Sheet Inputs_Calcs
A1: Inputs & Calculations — Multifamily Common Areas (Blended Rates)
A3: Project Name | B3: Ventura & 7th | D3: Units (count) | E3: 54 | G3: Electricity Rate ($/kWh) | H3: 0.22 | J3: Gas Rate ($/therm) | K3: 1.5 | M3: Billing Demand (kW) | N3: 0
G4: Demand $/kW | H4: 0 | J4: Fixed $/mo | K4: 0 | M4: Billing Months/Year | N4: 12
M5: Annual Demand $ | N5: =H4*N3*N4 -> 0
M6: Annual Fixed $ | N6: =K4*N4 -> 0
A8: DATA COLLECTION — Project Areas, Counts & Assumptions
A10: Areas by Type
A11: Area Type (matches lighting table) | B11: Area (ft²) | C11: Conditioned? (Yes/No) | D11: Ventilated? (Yes/No) | E11: Notes
A12: Corridor Area | B12: 7997.98 | C12: No | D12: Yes
A13: Stairwell | B13: 2474.9 | C13: No | D13: Yes
A14: Lobby, Main Entry | B14: 0 | C14: Yes | D14: Yes
A15: Lounge / Club Room | B15: 834.13 | C15: Yes | D15: Yes
A16: Exercise / Fitness | B16: 587.2 | C16: Yes | D16: Yes
A17: Office Area (> 250 ft²) | B17: 937.78 | C17: Yes | D17: Yes
A18: Office Area (≤ 250 ft²) | B18: 0 | C18: Yes | D18: Yes
A19: Restrooms (Common) | B19: 324.86 | C19: Yes | D19: Yes
A20: Laundry (Common) | B20: 610.88 | C20: Yes | D20: Yes
A21: Electrical/Mechanical/Telephone | B21: 3475.66 | C21: No | D21: Yes
A22: Storage – Warehouse | B22: 983.25 | C22: Yes | D22: Yes
A23: Kitchen / Food Prep | B23: 0 | C23: Yes | D23: Yes
A24: MFOther (blended preset) | B24: 0 | C24: Yes | D24: Yes | E24: Enter blended or non-blended not both
A25: Parking Garage | B25: 0 | C25: No | D25: Yes | E25: Enter this below in the Parking Garage inputs
A26: Blended Annual Rates — Electricity & Gas | B26: 0 | C26: Yes | D26: Yes | E26: Not developed yet
A27: Utility | B27: 0 | C27: Yes | D27: Yes
A28: PG&E | B28: 0 | C28: Yes | D28: Yes
A29: PG&E | B29: 0 | C29: Yes | D29: Yes
A30: PG&E | B30: 0 | C30: Yes | D30: Yes
A31: SCE | B31: 0 | C31: Yes | D31: Yes
A32: SCE | B32: 0 | C32: Yes | D32: Yes
A33: SCE | B33: 0 | C33: Yes | D33: Yes
A34: SDG&E | B34: 0 | C34: Yes | D34: Yes
A35: SDG&E | B35: 0 | C35: Yes | D35: Yes
A36: SDG&E | B36: 0 | C36: Yes | D36: Yes
A37: Other/Custom | B37: 0 | C37: Yes | D37: Yes
A38: Parking Garage | B38: 0 | C38: No | D38: Yes
A39: Surface Parking | B39: 0 | C39: No | D39: No
A41: Counts & Equipment
A42: # of Elevators | B42: 1
A43: Total Parking Spaces | B43: 82
A44: % EV Charger Spaces of Total | B44: 10
...

Sheet Definitions
A1: Definitions — Technical Terms & Inputs
A3: Term | B3: Definition / How Used
A4: LPD (Lighting Power Density, W/ft²) | B4: Watts of installed lighting per square foot. Used with area to compute connected kW: kW = Area × LPD / 1000.
A5: Control Factor (0–1) | B5: Represents average reduction from controls (e.g., occupancy/bi-level). 0.60 means 40% average reduction vs. full power.
A6: Diversity Factor (0–1) | B6: Represents non-simultaneous operation across a group. Commonly 0.90 for corridors; 1.00 otherwise.
A7: Blended Electricity Rate ($/kWh) | B7: Single average energy charge used across all kWh; excludes demand/fixed which are added separately.
A8: Demand Charge ($/kW) | B8: Monthly charge per billing kW; annual demand $ = $/kW × billing kW × months.
A9: Fixed Charge ($/mo) | B9: Monthly customer charge; annual fixed $ = $/mo × months.
A10: Hours/Day; Days/Year | B10: Operating schedule inputs used to derive annual hours.
A11: MFOther (blended preset) | B11: Temporary common-area lighting category with a blended LPD used before exact occupancy definitions are finalized.
A12: Mechanically Ventilated (Parking) | B12: Yes/No toggle. If Yes, ventilation energy is computed from fan W/ft², area, and hours.
A13: Installed Watts (Site Lighting) | B13: Total connected exterior lighting watts by category from NRCC-LTO prescriptive calculations.
A14: EV Charger % of Parking | B14: Percent of total parking spaces equipped with EV charging; used to estimate # of ports or spaces.

Sheet Lookups_References
A1: Lighting Power Densities — Title 24 (2022) Table 140.6-C (Common MF Spaces)
A2: Space Type | B2: LPD (W/ft²) | C2: Notes
A3: Corridor Area | B3: 0.4 | C3: Standard corridors
A4: Stairwell | B4: 0.6 | C4: Common stairwells
A5: Lobby, Main Entry | B5: 0.7 | C5: Entry lobby
A6: Lounge / Club Room | B6: 0.55 | C6: Amenity lounge/club room
A7: Exercise / Fitness | B7: 0.5 | C7: Fitness room/gym
A8: Office Area (> 250 ft²) | B8: 0.6 | C8: Leasing office
A9: Office Area (≤ 250 ft²) | B9: 0.65 | C9: Small office
A10: Restrooms (Common) | B10: 0.65
A11: Laundry (Common) | B11: 0.45
A12: Electrical/Mechanical/Telephone | B12: 0.4
A13: Storage – Warehouse | B13: 0.4
A14: Kitchen / Food Prep | B14: 0.95 | C14: Clubhouse kitchen
A15: MFOther (blended preset) | B15: 0.55 | C15: Use before occupancy definitions are finalized; replace with specific spaces later.
A16: Parking Garage | B16: 0.3 | C16: Placeholder LPD; edit per design / local code interpretation.
A17: Blended Annual Rates — Electricity & Gas
A18: Utility | B18: Class (kW range) | C18: Energy $/kWh | D18: Demand $/kW | E18: Fixed $/mo | F18: Tariff Code | G18: Effective Date | H18: Source / Notes
A19: PG&E | B19: Small (≤20 kW) | C19: 0.34 | D19: 0 | E19: 15 | F19: B-1 (Small General Service TOU) | G19: 2025-08 (planning default) | H19: Planning default; confirm latest PG&E tariff for project.
A20: PG&E | B20: Medium (20–200 kW) | C20: 0.27 | D20: 23 | E20: 150 | F20: E-19 / B-19 (verify) | G20: 2025-08 (planning default) | H20: Planning default; verify actual tariff selection and demand components.
A21: PG&E | B21: Large (>200 kW) | C21: 0.24 | D21: 28 | E21: 300 | F21: E-20 (verify) | G21: 2025-08 (planning default) | H21: Planning default; verify ratchets / transmission demand.
A22: SCE | B22: Small (≤20 kW) | C22: 0.28 | D22: 0 | E22: 16 | F22: TOU-GS-1 | G22: 2025-08 (planning default) | H22: Planning default for SCE GS-1.
A23: SCE | B23: Medium (20–200 kW) | C23: 0.24 | D23: 18 | E23: 100 | F23: TOU-GS-2 | G23: 2025-08 (planning default) | H23: Planning default for SCE GS-2 (demand).
A24: SCE | B24: Large (>200 kW) | C24: 0.22 | D24: 22 | E24: 150 | F24: TOU-GS-3 | G24: 2025-08 (planning default) | H24: Planning default for SCE GS-3 (demand).
A25: SDG&E | B25: Small (≤20 kW) | C25: 0.33 | D25: 0 | E25: 20 | F25: AL-TOU (Small) | G25: 2025-08 (planning default) | H25: Planning default for SDG&E AL-TOU small.
A26: SDG&E | B26: Medium (20–200 kW) | C26: 0.28 | D26: 20 | E26: 120 | F26: AL-TOU (Med) / AL-TOU2 | G26: 2025-08 (planning default) | H26: Planning default for SDG&E medium (demand).
A27: SDG&E | B27: Large (>200 kW) | C27: 0.26 | D27: 24 | E27: 180 | F27: AL-TOU (Large) / AL-TOU2 | G27: 2025-08 (planning default) | H27: Planning default for SDG&E large (demand).
A28: Other/Custom | B28: Any | C28: 0.3 | D28: 0 | E28: 0 | F28: Enter tariff | G28: 2025-08 (placeholder) | H28: Use for non-IOUs or custom blends.
A31: References & Sources (Traceability)
A32: Topic | B32: Reference / Source | C32: Notes (why/how used)
A33: LPD values | B33: CA Title 24, Part 6 (2022) — Table 140.6-C | C33: Used for interior common-area lighting power densities.
A34: Outdoor control schemes | B34: Title 24 §130.2 (Outdoor Lighting Controls) | C34: Default assumptions for hours/control; user can override.
A35: NRCC-LTO | B35: Nonresidential Certificate of Compliance (Outdoor Lighting) | C35: Installed Watts pasted into Site Lighting.
A36: DRE Budget mapping | B36: RE 623 Budget Worksheet (California DRE) | C36: Roll-up to 201 Electricity and 202 Gas for HOA budgets.
A37: Tariffs | B37: PG&E / SCE / SDG&E official rate sheets | C37: Enter blended annual $/kWh, demand $/kW, fixed $/mo.
A39: Pool Defaults | B39: Value
A40: Heater Load Factor (W/ft²) | B40: 10
A41: Heater Hours/Day | B41: 8
A42: Heater Days/Year | B42: 180
A43: Boiler Efficiency (0–1) | B43: 0.85
...

Sheet Report_Client
B2: Solar Cost Offset Calculation
A4: Project: 9th and Linden
A5: Date: 9/19/2025 | C5: Show therms | D5: Show kBtu | E5: Show Cost | F5: Show Gas
B6: Yes | C6: Yes | D6: Yes | E6: Yes | F6: Yes
A7: Solar Cost Offset Calculation - provides an estimate of the common area energy loads by applying the overall energy consumption percentage of T24 to the total building footprint. Design Phase Estimate - actual energy consumption will vary based on real-world usage patterns and operational conditions.
A9: Energy Use and Cost by Category
A10: Category | B10: kWh/yr | C10: therms/yr | D10: kBtu/yr | E10: $/yr
A11: EV Chargers (L2) | B11: =IF($B$6="Yes", Inputs_Calcs!B253, "") -> 15768 | C11: =IF($C$6="Yes", 0, "") -> 0 | D11: =IF($D$6="Yes", N(B11)*3.412 + N(C11)*100, "") -> 53800.416 | E11: =IF($E$6="Yes", Inputs_Calcs!B254, "") -> 3468.96
A12: EV Charging — subtotal | B12: =IF(B11="",0,B11) -> 15768 | C12: =IF(C11="",0,C11) -> 0 | D12: =IF(D11="",0,D11) -> 53800.416 | E12: =IF(E11="",0,E11) -> 3468.96
A13: Lighting — Site | B13: =IF($B$6="Yes", Inputs_Calcs!B255, "") -> 3000.3 | C13: =IF($C$6="Yes", 0, "") -> 0 | D13: =IF($D$6="Yes", N(B13)*3.412 + N(C13)*100, "") -> 10237.024 | E13: =IF($E$6="Yes", Inputs_Calcs!B256, "") -> 660.066
A14: Parking — Lighting | B14: =IF($B$6="Yes", Inputs_Calcs!B157, "") -> 0 | C14: =IF($C$6="Yes", 0, "") -> 0 | D14: =IF($D$6="Yes", N(B14)*3.412 + N(C14)*100, "") -> 0 | E14: =IF($E$6="Yes", Inputs_Calcs!B257, "") -> 0
A15: Exterior Lighting — subtotal | B15: =IF(B16+B13+B14="",0,B16+B13+B14) -> 32449.471 | C15: =IF(C16+C13+C14="",0,C16+C13+C14) -> 0 | D15: =IF(D16+D13+D14="",0,D16+D13+D14) -> 110717.6 | E15: =IF(E16+E13+E14="",0,E16+E13+E14) -> 7138.8837
A16: Lighting — Interior | B16: =IF($B$6="Yes", Inputs_Calcs!B249, "") -> 29449.171 | C16: =IF($C$6="Yes", 0, "") -> 0 | D16: =IF($D$6="Yes", N(B16)*3.412 + N(C16)*100, "") -> 100480.57 | E16: =IF($E$6="Yes", Inputs_Calcs!B250, "") -> 6478.8177
A17: HVAC — Heating (HP) | B17: =IF($B$6="Yes", Inputs_Calcs!B236, "") -> 8556.2 | C17: =IF($C$6="Yes", 0, "") -> 0 | D17: =IF($D$6="Yes", N(B17)*3.412 + N(C17)*100, "") -> 29193.754 | E17: =IF($E$6="Yes", Inputs_Calcs!B265, "") -> 1882.364
A18: HVAC — Cooling | B18: =IF($B$6="Yes", Inputs_Calcs!B241, "") -> 6417.15 | C18: =IF($C$6="Yes", 0, "") -> 0 | D18: =IF($D$6="Yes", N(B18)*3.412 + N(C18)*100, "") -> 21895.316 | E18: =IF($E$6="Yes", Inputs_Calcs!B267, "") -> 1411.773
A19: HVAC — Ventilation | B19: =IF($B$6="Yes", Inputs_Calcs!B244, "") -> 47899.61 | C19: =IF($C$6="Yes", 0, "") -> 0 | D19: =IF($D$6="Yes", N(B19)*3.412 + N(C19)*100, "") -> 163433.47 | E19: =IF($E$6="Yes", Inputs_Calcs!B268, "") -> 10537.914
A20: DHW * | B20: =5200*1.03 -> 5356
A21: Modeled Energy Use | B21: =IF(B17+B18+B19="",0,B17+B18+B19) -> 62872.96 | C21: =IF(C17+C18+C19="",0,C17+C18+C19) -> 0 | D21: =IF(D17+D18+D19="",0,D17+D18+D19) -> 214522.54 | E21: =IF(E17+E18+E19="",0,E17+E18+E19) -> 13832.051
A22: Parking — Ventilation | B22: =IF($B$6="Yes", Inputs_Calcs!B164, "") -> 0 | C22: =IF($C$6="Yes", 0, "") -> 0 | D22: =IF($D$6="Yes", N(B22)*3.412 + N(C22)*100, "") -> 0 | E22: =IF($E$6="Yes", Inputs_Calcs!B258, "") -> 0
A23: Parking (Ventilation) — subtotal | B23: =IF(B22="",0,B22) -> 0 | C23: =IF(C22="",0,C22) -> 0 | D23: =IF(D22="",0,D22) -> 0 | E23: =IF(E22="",0,E22) -> 0
A24: Elevators | B24: =IF($B$6="Yes", Inputs_Calcs!B251, "") -> 16000 | C24: =IF($C$6="Yes", 0, "") -> 0 | D24: =IF($D$6="Yes", N(B24)*3.412 + N(C24)*100, "") -> 54592 | E24: =IF($E$6="Yes", Inputs_Calcs!B252, "") -> 3520
A25: Elevators — subtotal | B25: =IF(B24="",0,B24) -> 16000 | C25: =IF(C24="",0,C24) -> 0 | D25: =IF(D24="",0,D24) -> 54592 | E25: =IF(E24="",0,E24) -> 3520
A26: Pools — Pumps | B26: =IF($B$6="Yes", Inputs_Calcs!B259, "") -> 0 | C26: =IF($C$6="Yes", 0, "") -> 0 | D26: =IF($D$6="Yes", N(B26)*3.412 + N(C26)*100, "") -> 0 | E26: =IF($E$6="Yes", Inputs_Calcs!B260, "") -> 0
A27: Pools — Heater (Electric/HP) | B27: =IF($B$6="Yes", Inputs_Calcs!B261, "") -> 0 | C27: =IF($C$6="Yes", 0, "") -> 0 | D27: =IF($D$6="Yes", N(B27)*3.412 + N(C27)*100, "") -> 0 | E27: =IF($E$6="Yes", Inputs_Calcs!B263, "") -> 0
A28: Pools — Heater (Gas) | B28: =IF($B$6="Yes", 0, "") -> 0 | C28: =IF(AND($C$6="Yes",$F$6="Yes"), Inputs_Calcs!B262, "") -> 0 | D28: =IF($D$6="Yes", N(B28)*3.412 + N(C28)*100, "") -> 0 | E28: =IF(AND($E$6="Yes",$F$6="Yes"), Inputs_Calcs!B264, "") -> 0
A29: Pools — subtotal | B29: =IF(B26+B27+B28="",0,B26+B27+B28) -> 0 | C29: =IF(C26+C27+C28="",0,C26+C27+C28) -> 0 | D29: =IF(D26+D27+D28="",0,D26+D27+D28) -> 0 | E29: =IF(E26+E27+E28="",0,E26+E27+E28) -> 0
A30: Extra HPWH load | B30: 0
A31: Fire Pump | B31: =Inputs_Calcs!B205 -> 58.614286
A32: Booster Pumps | B32: =Inputs_Calcs!B213 -> 8760
A33: Recirc Pumps | B33: =Inputs_Calcs!B221 -> 4667.8286
A34: Water Softener | B34: =Inputs_Calcs!B229 -> 0
A35: Elevator Shaft RTU | B35: 0
A36: Starewell Freeze Protection | B36: 0
A37: Grand Total | B37: =B16+B13+B14+B22+B24+B11+B26+B27+B28+B17+B18+B19+B31+B32+B33+B34+B35+B36+B30 -> 140576.87 | C37: =C16+C13+C14+C22+C24+C11+C26+C27+C28+C17+C18+C19 -> 0 | D37: =D16+D13+D14+D22+D24+D11+D26+D27+D28+D17+D18+D19 -> 433632.55 | E37: =E16+E13+E14+E22+E24+E11+E26+E27+E28+E17+E18+E19 -> 27959.895
A38: Without EV | B38: =B37-B12 -> 124808.87
A40: Total (wth modeled) | B40: 564584
A41: Total (No EV) | B41: =B38+424107 -> 548915.87
A43: Reference / Source | C43: Notes
A44: CA Title 24, Part 6 (2022) — Table 140.6-C | C44: Used for interior common-area lighting power densities.
A45: Title 24 §130.2 (Outdoor Lighting Controls) | C45: Default assumptions for hours/control; user can override.
...
