Workbook
Name heater_efficiency: 'Pool Energy Use Calculator'!$C$34
Name Monthsperyear: 'pump assumptions & calcs'!$C$34
Name poolcover: 'Pool Energy Use Calculator'!$C$30
Name turnovers: 'pump assumptions & calcs'!$C$40

Sheet Summary
A2: Common Area Energy Use | B2: This field pulls from the HourlyResults tab and represents the total energy use for nonresidential spaces per the energy model. Please refer to House Meter SOP to develop correct model
A3: Pool Energy Use | B3: This field pulls from the Pool Energy Calculator and then splits the energy usage per month based on the common area usage per month. We are assuming that high nonresidential energy use corresponds to a colder month and therefore the pool will require more heating.
A4: Site Lighting Energy Use | B4: This field represents all the lighting on site that the house will be responsible for. Count up all the lights in nonresidential zones and parking areas and sum up the corresponding wattage. Input that value into Total Site Lighting Energy Use. Colder months have longer nights and will require more light.
A5: EV Charging Energy Use | B5: This field pulls from the EV Calculator and then splits the energy usage per month based on the common area usage per month. We are assuming equal charging use per month
A6: *DO NOT DELETE any columns. HIDE any columns unneed for project.
A7: ** Complete all relevant calculators
B9: PROJECT NAME - Building Number
B10: Month | C10: Common Area Energy Usage (kWh) | D10: Pool Gas Usage (MBTU) | E10: Pool Energy Usage (kWh) | F10: Site Lighting Energy Usage (kW) | G10: EV Charging Energy Usage (kWh) | H10: Total kWh
B11: 1 | C11: =IF(SUMIF('ap-HourlyResults'!$A$19:$A$8778,Summary!$B11,'ap-HourlyResults'!$Q$19:$Q$8778)=0,"-",SUMIF('ap-HourlyResults'!$A$19:$A$8778,Summary!$B11,'ap-HourlyResults'!$Q$19:$Q$8778)) -> - | D11: =IFERROR(C11/$C$23*$D$23,"-") -> - | E11: =IFERROR(C11/$C$23*$E$23,"-") -> - | F11: =IF(IFERROR(C11/$C$23*$F$23,"-")=0,"-",IFERROR(C11/$C$23*$F$23,"-")) -> - | G11: =IF(IFERROR($G$23/12,"-")=0,"-",IFERROR($G$23/12,"-")) -> - | H11: =SUM(G11,F11,E11,C11) -> 0
B12: 2 | C12: =IF(SUMIF('ap-HourlyResults'!$A$19:$A$8778,Summary!$B12,'ap-HourlyResults'!$Q$19:$Q$8778)=0,"-",SUMIF('ap-HourlyResults'!$A$19:$A$8778,Summary!$B12,'ap-HourlyResults'!$Q$19:$Q$8778)) -> - | D12: =IFERROR(C12/$C$23*$D$23,"-") -> - | E12: =IFERROR(C12/$C$23*$E$23,"-") -> - | F12: =IF(IFERROR(C12/$C$23*$F$23,"-")=0,"-",IFERROR(C12/$C$23*$F$23,"-")) -> - | G12: =IF(IFERROR($G$23/12,"-")=0,"-",IFERROR($G$23/12,"-")) -> - | H12: =SUM(G12,F12,E12,C12) -> 0
B13: 3 | C13: =IF(SUMIF('ap-HourlyResults'!$A$19:$A$8778,Summary!$B13,'ap-HourlyResults'!$Q$19:$Q$8778)=0,"-",SUMIF('ap-HourlyResults'!$A$19:$A$8778,Summary!$B13,'ap-HourlyResults'!$Q$19:$Q$8778)) -> - | D13: =IFERROR(C13/$C$23*$D$23,"-") -> - | E13: =IFERROR(C13/$C$23*$E$23,"-") -> - | F13: =IF(IFERROR(C13/$C$23*$F$23,"-")=0,"-",IFERROR(C13/$C$23*$F$23,"-")) -> - | G13: =IF(IFERROR($G$23/12,"-")=0,"-",IFERROR($G$23/12,"-")) -> - | H13: =SUM(G13,F13,E13,C13) -> 0
B14: 4 | C14: =IF(SUMIF('ap-HourlyResults'!$A$19:$A$8778,Summary!$B14,'ap-HourlyResults'!$Q$19:$Q$8778)=0,"-",SUMIF('ap-HourlyResults'!$A$19:$A$8778,Summary!$B14,'ap-HourlyResults'!$Q$19:$Q$8778)) -> - | D14: =IFERROR(C14/$C$23*$D$23,"-") -> - | E14: =IFERROR(C14/$C$23*$E$23,"-") -> - | F14: =IF(IFERROR(C14/$C$23*$F$23,"-")=0,"-",IFERROR(C14/$C$23*$F$23,"-")) -> - | G14: =IF(IFERROR($G$23/12,"-")=0,"-",IFERROR($G$23/12,"-")) -> - | H14: =SUM(G14,F14,E14,C14) -> 0
B15: 5 | C15: =IF(SUMIF('ap-HourlyResults'!$A$19:$A$8778,Summary!$B15,'ap-HourlyResults'!$Q$19:$Q$8778)=0,"-",SUMIF('ap-HourlyResults'!$A$19:$A$8778,Summary!$B15,'ap-HourlyResults'!$Q$19:$Q$8778)) -> - | D15: =IFERROR(C15/$C$23*$D$23,"-") -> - | E15: =IFERROR(C15/$C$23*$E$23,"-") -> - | F15: =IF(IFERROR(C15/$C$23*$F$23,"-")=0,"-",IFERROR(C15/$C$23*$F$23,"-")) -> - | G15: =IF(IFERROR($G$23/12,"-")=0,"-",IFERROR($G$23/12,"-")) -> - | H15: =SUM(G15,F15,E15,C15) -> 0
B16: 6 | C16: =IF(SUMIF('ap-HourlyResults'!$A$19:$A$8778,Summary!$B16,'ap-HourlyResults'!$Q$19:$Q$8778)=0,"-",SUMIF('ap-HourlyResults'!$A$19:$A$8778,Summary!$B16,'ap-HourlyResults'!$Q$19:$Q$8778)) -> - | D16: =IFERROR(C16/$C$23*$D$23,"-") -> - | E16: =IFERROR(C16/$C$23*$E$23,"-") -> - | F16: =IF(IFERROR(C16/$C$23*$F$23,"-")=0,"-",IFERROR(C16/$C$23*$F$23,"-")) -> - | G16: =IF(IFERROR($G$23/12,"-")=0,"-",IFERROR($G$23/12,"-")) -> - | H16: =SUM(G16,F16,E16,C16) -> 0
B17: 7 | C17: =IF(SUMIF('ap-HourlyResults'!$A$19:$A$8778,Summary!$B17,'ap-HourlyResults'!$Q$19:$Q$8778)=0,"-",SUMIF('ap-HourlyResults'!$A$19:$A$8778,Summary!$B17,'ap-HourlyResults'!$Q$19:$Q$8778)) -> - | D17: =IFERROR(C17/$C$23*$D$23,"-") -> - | E17: =IFERROR(C17/$C$23*$E$23,"-") -> - | F17: =IF(IFERROR(C17/$C$23*$F$23,"-")=0,"-",IFERROR(C17/$C$23*$F$23,"-")) -> - | G17: =IF(IFERROR($G$23/12,"-")=0,"-",IFERROR($G$23/12,"-")) -> - | H17: =SUM(G17,F17,E17,C17) -> 0
B18: 8 | C18: =IF(SUMIF('ap-HourlyResults'!$A$19:$A$8778,Summary!$B18,'ap-HourlyResults'!$Q$19:$Q$8778)=0,"-",SUMIF('ap-HourlyResults'!$A$19:$A$8778,Summary!$B18,'ap-HourlyResults'!$Q$19:$Q$8778)) -> - | D18: =IFERROR(C18/$C$23*$D$23,"-") -> - | E18: =IFERROR(C18/$C$23*$E$23,"-") -> - | F18: =IF(IFERROR(C18/$C$23*$F$23,"-")=0,"-",IFERROR(C18/$C$23*$F$23,"-")) -> - | G18: =IF(IFERROR($G$23/12,"-")=0,"-",IFERROR($G$23/12,"-")) -> - | H18: =SUM(G18,F18,E18,C18) -> 0
B19: 9 | C19: =IF(SUMIF('ap-HourlyResults'!$A$19:$A$8778,Summary!$B19,'ap-HourlyResults'!$Q$19:$Q$8778)=0,"-",SUMIF('ap-HourlyResults'!$A$19:$A$8778,Summary!$B19,'ap-HourlyResults'!$Q$19:$Q$8778)) -> - | D19: =IFERROR(C19/$C$23*$D$23,"-") -> - | E19: =IFERROR(C19/$C$23*$E$23,"-") -> - | F19: =IF(IFERROR(C19/$C$23*$F$23,"-")=0,"-",IFERROR(C19/$C$23*$F$23,"-")) -> - | G19: =IF(IFERROR($G$23/12,"-")=0,"-",IFERROR($G$23/12,"-")) -> - | H19: =SUM(G19,F19,E19,C19) -> 0
B20: 10 | C20: =IF(SUMIF('ap-HourlyResults'!$A$19:$A$8778,Summary!$B20,'ap-HourlyResults'!$Q$19:$Q$8778)=0,"-",SUMIF('ap-HourlyResults'!$A$19:$A$8778,Summary!$B20,'ap-HourlyResults'!$Q$19:$Q$8778)) -> - | D20: =IFERROR(C20/$C$23*$D$23,"-") -> - | E20: =IFERROR(C20/$C$23*$E$23,"-") -> - | F20: =IF(IFERROR(C20/$C$23*$F$23,"-")=0,"-",IFERROR(C20/$C$23*$F$23,"-")) -> - | G20: =IF(IFERROR($G$23/12,"-")=0,"-",IFERROR($G$23/12,"-")) -> - | H20: =SUM(G20,F20,E20,C20) -> 0
B21: 11 | C21: =IF(SUMIF('ap-HourlyResults'!$A$19:$A$8778,Summary!$B21,'ap-HourlyResults'!$Q$19:$Q$8778)=0,"-",SUMIF('ap-HourlyResults'!$A$19:$A$8778,Summary!$B21,'ap-HourlyResults'!$Q$19:$Q$8778)) -> - | D21: =IFERROR(C21/$C$23*$D$23,"-") -> - | E21: =IFERROR(C21/$C$23*$E$23,"-") -> - | F21: =IF(IFERROR(C21/$C$23*$F$23,"-")=0,"-",IFERROR(C21/$C$23*$F$23,"-")) -> - | G21: =IF(IFERROR($G$23/12,"-")=0,"-",IFERROR($G$23/12,"-")) -> - | H21: =SUM(G21,F21,E21,C21) -> 0
B22: 12 | C22: =IF(SUMIF('ap-HourlyResults'!$A$19:$A$8778,Summary!$B22,'ap-HourlyResults'!$Q$19:$Q$8778)=0,"-",SUMIF('ap-HourlyResults'!$A$19:$A$8778,Summary!$B22,'ap-HourlyResults'!$Q$19:$Q$8778)) -> - | D22: =IFERROR(C22/$C$23*$D$23,"-") -> - | E22: =IFERROR(C22/$C$23*$E$23,"-") -> - | F22: =IF(IFERROR(C22/$C$23*$F$23,"-")=0,"-",IFERROR(C22/$C$23*$F$23,"-")) -> - | G22: =IF(IFERROR($G$23/12,"-")=0,"-",IFERROR($G$23/12,"-")) -> - | H22: =SUM(G22,F22,E22,C22) -> 0
B23: Total | C23: =SUM(C$11:C$22) -> 0 | D23: =IF('Pool Energy Use Calculator'!$C$28="Gas / Propane",'Pool Energy Use Calculator'!F29,"-") -> - | E23: =IF('Pool Energy Use Calculator'!$C$28="Gas / Propane",'Pool Energy Use Calculator'!$F$44,'Pool Energy Use Calculator'!$F$29+'Pool Energy Use Calculator'!$F$44) -> 0 | F23: - | G23: ='EV Calculator'!D6 -> 0 | H23: =SUM(H11:H22) -> 0
A26: *See TMP Building 1 for Example (T:\Projects\60-22111-AO-IAC- TMP Marketplace Bldg1\10_Energy Model\Energy Use Report)

Sheet EV Calculator
C2: EV Total Energy Use
C3: Number of EV parking spaces
C4: Energy Consumption per EV Monthly* | D4: 394
C5: Ratio of EV charges daily to EV parking spaces | D5: 1
C6: Yearly kWh from EV charging | D6: =D3*D4*D5 -> 0
C8: *https://www.edmunds.com/electric-car/articles/how-much-electricity-does-an-ev-use.html

Sheet Pool Energy Use Calculator
B2: Pool Energy Use Calculator for LEED for Homes Single-family Projects
B3: This calculator is only designed to assist LEED for Homes projects with estimating pool heating and pump energy use for the purposes of EA Annual Energy Use, and is not
B4: intended to be used as a prediction for project teams or manufacturers.
B5: *Note that this calculator is currently in draft format. Projects may email homestechnical@gbci.org to request project-specific approval to use this calculator
B6: in advance of formal approval of the calculator. When this calculator is finalized, projects are expected to use the final published version.
B7: PROJECT DETAILS
B9: Project location: | C9: California
B11: Project climate zone: | C11: 3B
B13: Pool surface area (sqft):
B15: Average pool depth (ft): | C15: 5
B17: Pool volume (gallons): | C17: =C13*C15*7.48052 -> 0
B19: Expected pool use (months/yr): | C19: 12 | D19: =IF(C9="","",IF(C19="not sure (use default)"," default estimate for this location: "&Monthsperyear&" months/yr",""))
B25: POOL HEATING ENERGY USE
F27: Estimated Pool Heating Energy Use:
B28: Type of pool heater: | C28: Heat pump
F29: =IF(C9="","",IF(C28="Gas / propane",ROUNDDOWN('htg assumptions & calcs'!C7,-1),ROUNDDOWN('htg assumptions & calcs'!C8,-2))) -> 0 | G29: =IF(C28="Gas / Propane","MBTU/year","kWh/year") -> kWh/year | H29: =IF(C28="Heat pump","("&ROUNDDOWN('htg assumptions & calcs'!C7,1)&" MBTU/yr)","") -> (0 MBTU/yr)
B30: Is a pool cover installed? | C30: no
B32: Expected setpoint: | C32: 80
B34: Pool heater efficiency: | C34: 3 | D34: =IF(C28="Gas / Propane","Et (input as decimal)","COP") -> COP
B40: POOL PUMP ENERGY USE
F42: Estimated Pool Pump Energy Use:
B43: Pump nameplate HP | C43: 2
F44: =IF(C9="","",ROUNDDOWN(C17*'pump assumptions & calcs'!C40/(C51*1000)*(30.4*Monthsperyear),-2)) -> 0 | G44: kWh/year
B45: Is the pump ENERGY STAR labeled? | C45: No
B47: Single-speed or variable speed? | C47: single-speed
B49: Turnovers per day? | C49: 2 | D49: =IF(C9="","",IF(C49="not sure (use default)"," default estimate for this location: "&turnovers&" turnovers/day",""))
B51: Pump energy factor (kgallons/kWh) | C51: =IF(C43="","",'pump assumptions & calcs'!C29) -> 2.2990493 | D51: The energy factor is calculated automatically based on the characteristics of the pump, but it can be over-written by the user.
D52: If an ENERGY STAR pump is installed, the product-specific energy factor can be found here:
D53: https://www.energystar.gov/productfinder/product/certified-pool-pumps/results
B58: Published by GBCI, December, 2023

Sheet ap-HourlyResults
A1: **Paste ap-HourlyResults for all Nonresidential Spaces here. It does not matter whether all 'ResOtherZn's were converted to 'Spc' or if all 'ResZn's were removed**

Sheet pump assumptions & calcs
B3: Conventional (single speed) pump
E4: Nameplate Horsepower
E5: 3 | F5: 2.5 | G5: 2 | H5: 1.5 | I5: 1
B6: Curve C - Energy Factor (Gal/Wh) | E6: 1.9986894 | F6: 2.1812026 | G6: 2.2990493 | H6: 2.2676708 | I6: 2.5131761
B7: Curve C - Flow (GPM) | E7: 101.66667 | F7: 93.091 | G7: 88.666667 | H7: 78.142857 | I7: 75.5
B9: Variable-speed pump
E10: Nameplate Horsepower at High Speed
E11: 1.65 hhp (3 HP) | F11: 1.25 hhp (2.5 HP) | G11: 1.18 hhp (2 HP) | H11: 0.95 hhp (1.65 HP) | I11: 0.72 hhp (1-1.4 HP)
E12: 3 | F12: 2.5 | G12: 2 | H12: 1.5 | I12: 1
B13: Curve C - Weighted Energy Factor (Gal/Wh) | E13: 7.1 | F13: 7.4 | G13: 9.3 | H13: 8.9 | I13: 8.7
B14: Curve C - High Flow (GPM) | E14: 102 | F14: 90 | G14: 89.714286 | H14: 78 | I14: 70
B15: Curve C - Low Energy Factor (Gal/Wh) | E15: 6.0714286 | F15: 5.9565217 | G15: 6.4985881 | H15: 6.7090726 | I15: 6.7787115
B16: Curve C - Low Flow (GPM) | E16: 51 | F16: 45.666667 | G16: 44.75 | H16: 41.75 | I16: 40.333333
B17: Source: ENERGY STAR Pool Pump Calculator (https://www.energystar.gov/productfinder/downloads/Pool_Pump_Calculator_2020.05.05_FINAL.xlsx)
B19: pump type (dropdown menu)
B20: not sure (use default)
B21: single-speed
B22: variable-speed
B25: Pump energy factor (kgallons/kWh)
B26: Nameplate HP | C26: ='Pool Energy Use Calculator'!C43 -> 2
B27: ENERGY STAR? | C27: ='Pool Energy Use Calculator'!C45 -> No
B28: pump type: | C28: =IF('Pool Energy Use Calculator'!C47=B20,IF(C27="no","single-speed","variable-speed"),'Pool Energy Use Calculator'!C47) -> single-speed
B29: pump energy factor: | C29: =IF(C28=B21,HLOOKUP(C26,E5:I6,2,FALSE),IF(C28=B22,HLOOKUP(C26,E12:I13,2,FALSE))) -> 2.2990493 | D29: (gallons/Wh)
B31: Estimated pool use (months/year)
B32: user input: | C32: ='Pool Energy Use Calculator'!C19 -> 12
B33: default | C33: =VLOOKUP(E33,B45:E95,3,FALSE) -> 12 | D33: for | E33: ='Pool Energy Use Calculator'!C9 -> California
B34: estimated use (mo/yr): | C34: =IF('Pool Energy Use Calculator'!C19="not sure (use default)",C33,'Pool Energy Use Calculator'!C19) -> 12
B37: Pump Turnover
B38: user input: | C38: ='Pool Energy Use Calculator'!C49 -> 2
B39: default | C39: =VLOOKUP(E33,B45:E95,4,FALSE) -> 1 | D39: for | E39: ='Pool Energy Use Calculator'!C9 -> California
B40: estimated turnover: | C40: =IF('Pool Energy Use Calculator'!C49="not sure (use default)",C39,'Pool Energy Use Calculator'!C49) -> 2
B44: State | C44: Climate | D44: Use (months/yr) | E44: Turnovers per day
B45: Alabama | C45: Warm | D45: 12 | E45: =IF(C45="warm",1,2) -> 1
B46: Alaska | C46: Cool | D46: 5 | E46: =IF(C46="warm",1,2) -> 2
B47: Arizona | C47: Warm | D47: 12 | E47: =IF(C47="warm",1,2) -> 1
B48: Arkansas | C48: Warm | D48: 12 | E48: =IF(C48="warm",1,2) -> 1
B49: California | C49: Warm | D49: 12 | E49: =IF(C49="warm",1,2) -> 1
B50: Colorado | C50: Warm | D50: 4 | E50: =IF(C50="warm",1,2) -> 1
B51: Connecticut | C51: Cool | D51: 4 | E51: =IF(C51="warm",1,2) -> 2
B52: Delaware | C52: Cool | D52: 5 | E52: =IF(C52="warm",1,2) -> 2
...

Sheet htg assumptions & calcs
B2: Calculated Pool Energy Use (back-end)
B4: MBTU/sqft/month: | C4: =IF('Pool Energy Use Calculator'!C28="Gas / Propane",IF(poolcover="yes",M34,M33),IF(poolcover="yes",U34,U33)) -> 0.028329355
B5: MBTU/month: | C5: =C4*'Pool Energy Use Calculator'!C13 -> 0
B6: MBTU/year load | C6: =Monthsperyear*C5 -> 0
B7: MBTU/year energy use (w/ eff) | C7: =C6/heater_efficiency -> 0
B8: kWh/yr energy use | C8: =C7*293.071 -> 0
B18: DATA USED IN CALCULATIONS (based on DOE)
M19: GAS OR PROPANE | Q19: HEAT PUMP | U19: HEAT PUMP
E20: Typical Months | M20: ENERGY USE | Q20: ENERGY USE | U20: ENERGY USE
B21: COVER? | C21: CLIMATE ZONE | D21: Notes | M21: (MBTU/sqft/month) @ 100% | Q21: (kWh/sqft/month) @ 1 COP | U21: (MBTU/sqft/month) @ 1 COP
M22: 78° | N22: 80° | O22: 82° | Q22: 78° | R22: 80° | S22: 82° | U22: 78° | V22: 80° | W22: 82°
B23: no cover | C23: 1 | E23: 12 | M23: =M53 -> 0.017798171 | N23: =N53 -> 0.023730895 | O23: =O53 -> 0.029996917 | Q23: =Q53 -> 4.7995004 | R23: =R53 -> 6.370246 | S23: =S53 -> 8.0500711 | U23: =Q23/293.071 -> 0.016376579 | V23: =R23/293.071 -> 0.021736187 | W23: =S23/293.071 -> 0.027467989
B24: no cover | C24: 2 | E24: 8 | M24: =M55 -> 0.017298222 | N24: =N55 -> 0.022197719 | O24: =O55 -> 0.027697154 | Q24: =Q55 -> 4.4504458 | R24: =R55 -> 5.7266766 | S24: =S55 -> 7.1338028 | U24: =Q24/293.071 -> 0.015185555 | V24: =R24/293.071 -> 0.019540236 | W24: =S24/293.071 -> 0.024341552
B25: no cover | C25: 3A | D25: avg Dallas & Atlanta | E25: 7 | M25: =AVERAGE(M57,M59) -> 0.022969068 | N25: =AVERAGE(N57,N59) -> 0.029768369 | O25: =AVERAGE(O57,O59) -> 0.038110369 | Q25: =AVERAGE(Q57,Q59) -> 5.9837927 | R25: =AVERAGE(R57,R59) -> 7.7789305 | S25: =AVERAGE(S57,S59) -> 9.9667547 | U25: =Q25/293.071 -> 0.020417553 | V25: =R25/293.071 -> 0.026542819 | W25: =S25/293.071 -> 0.034007987
B26: no cover | C26: 3B | E26: 6 | M26: =M59 -> 0.024340356 | N26: =N59 -> 0.032110986 | O26: =O59 -> 0.04113863 | Q26: =Q59 -> 6.2829823 | R26: =R59 -> 8.3025124 | S26: =S59 -> 10.658631 | U26: =Q26/293.071 -> 0.021438431 | V26: =R26/293.071 -> 0.028329355 | W26: =S26/293.071 -> 0.036368766
B27: no cover | C27: 3C | D27: use Los Angeles data - San Francisco is not typical | E27: 6 | M27: =M61 -> 0.031063474 | N27: =N61 -> 0.039595931 | O27: =O61 -> 0.048395027 | Q27: =Q61 -> 8.2900461 | R27: =R61 -> 10.558901 | S27: =S61 -> 12.958651 | U27: =Q27/293.071 -> 0.028286818 | V27: =R27/293.071 -> 0.036028474 | W27: =S27/293.071 -> 0.044216763
B28: no cover | C28: 4 | D28: avg Kansas City, New York, Seattle | E28: 6 | M28: =AVERAGE(M65,M67,M69) -> 0.034560893 | N28: =AVERAGE(N65,N67,N69) -> 0.042911146 | O28: =AVERAGE(O65,O67,O69) -> 0.051976881 | Q28: =AVERAGE(Q65,Q67,Q69) -> 9.142321 | R28: =AVERAGE(R65,R67,R69) -> 11.358818 | S28: =AVERAGE(S65,S67,S69) -> 13.726571 | U28: =Q28/293.071 -> 0.031194902 | V28: =R28/293.071 -> 0.038757904 | W28: =S28/293.071 -> 0.046837016
B29: no cover | C29: 5 | D29: avg Chicago, Denver, Boston | E29: 4 | M29: =AVERAGE(M71,M73,M75) -> 0.039710919 | N29: =AVERAGE(N71,N73,N75) -> 0.048941637 | O29: =AVERAGE(O71,O73,O75) -> 0.05858398 | Q29: =AVERAGE(Q71,Q73,Q75) -> 10.462911 | R29: =AVERAGE(R71,R73,R75) -> 12.906293 | S29: =AVERAGE(S71,S73,S75) -> 15.450028 | U29: =Q29/293.071 -> 0.035700942 | V29: =R29/293.071 -> 0.04403811 | W29: =S29/293.071 -> 0.052717697
B30: no cover | C30: 6 | D30: avg CZ 5 and CZ 7 (no data) | E30: 4 | M30: =AVERAGE(M29,M31) -> 0.03649125 | N30: =AVERAGE(N29,N31) -> 0.046668538 | O30: =AVERAGE(O29,O31) -> 0.056489195 | Q30: =AVERAGE(Q29,Q31) -> 9.5510058 | R30: =AVERAGE(R29,R31) -> 12.016204 | S30: =AVERAGE(S29,S31) -> 14.531578 | U30: =Q30/293.071 -> 0.032589392 | V30: =R30/293.071 -> 0.041000999 | W30: =S30/293.071 -> 0.049583815
B31: no cover | C31: 7 | E31: 4 | M31: =M77 -> 0.033271581 | N31: =N77 -> 0.044395438 | O31: =O77 -> 0.05439441 | Q31: =Q77 -> 8.6391007 | R31: =R77 -> 11.126115 | S31: =S77 -> 13.613128 | U31: =Q31/293.071 -> 0.029477842 | V31: =R31/293.071 -> 0.037963888 | W31: =S31/293.071 -> 0.046449933
M32: =LOOKUP('Pool Energy Use Calculator'!$C$11,$C23:$C31,M23:M31) -> 0.024340356 | N32: =LOOKUP('Pool Energy Use Calculator'!$C$11,$C23:$C31,N23:N31) -> 0.032110986 | O32: =LOOKUP('Pool Energy Use Calculator'!$C$11,$C23:$C31,O23:O31) -> 0.04113863 | Q32: =LOOKUP('Pool Energy Use Calculator'!$C$11,$C23:$C31,Q23:Q31) -> 6.2829823 | R32: =LOOKUP('Pool Energy Use Calculator'!$C$11,$C23:$C31,R23:R31) -> 8.3025124 | S32: =LOOKUP('Pool Energy Use Calculator'!$C$11,$C23:$C31,S23:S31) -> 10.658631 | U32: =LOOKUP('Pool Energy Use Calculator'!$C$11,$C23:$C31,U23:U31) -> 0.021438431 | V32: =LOOKUP('Pool Energy Use Calculator'!$C$11,$C23:$C31,V23:V31) -> 0.028329355 | W32: =LOOKUP('Pool Energy Use Calculator'!$C$11,$C23:$C31,W23:W31) -> 0.036368766
K33: LOOKUP W/ NO COVER --> | M33: =IF('Pool Energy Use Calculator'!C32="not sure (use default)",M32,IF('Pool Energy Use Calculator'!C32=78,M32,IF('Pool Energy Use Calculator'!C32=80,N32,IF('Pool Energy Use Calculator'!C32=82,O32)))) -> 0.032110986 | Q33: =U33*293.071 -> 8.3025124 | U33: =IF('Pool Energy Use Calculator'!C32="not sure (use default)",U32,IF('Pool Energy Use Calculator'!C32=78,U32,IF('Pool Energy Use Calculator'!C32=80,V32,IF('Pool Energy Use Calculator'!C32=82,W32)))) -> 0.028329355
K34: LOOKUP W/ COVER --> | M34: =IF('Pool Energy Use Calculator'!C32="not sure (use default)",M35,IF('Pool Energy Use Calculator'!C32=78,M35,IF('Pool Energy Use Calculator'!C32=80,N35,IF('Pool Energy Use Calculator'!C32=82,O35)))) -> 0.0060565205 | U34: =IF('Pool Energy Use Calculator'!C32="not sure (use default)",U35,IF('Pool Energy Use Calculator'!C32=78,U35,IF('Pool Energy Use Calculator'!C32=80,V35,IF('Pool Energy Use Calculator'!C32=82,W35)))) -> 0.005231998
E35: =LOOKUP('Pool Energy Use Calculator'!$C$11,$C36:$C44,E36:E44) -> 6 | F35: <== LOOKUP DEFAULT # OF MONTHS | M35: =LOOKUP('Pool Energy Use Calculator'!$C$11,$C36:$C44,M36:M44) -> 0.0045709588 | N35: =LOOKUP('Pool Energy Use Calculator'!$C$11,$C36:$C44,N36:N44) -> 0.0060565205 | O35: =LOOKUP('Pool Energy Use Calculator'!$C$11,$C36:$C44,O36:O44) -> 0.0084562739 | Q35: =LOOKUP('Pool Energy Use Calculator'!$C$11,$C36:$C44,Q36:Q44) -> 1.1593598 | R35: =LOOKUP('Pool Energy Use Calculator'!$C$11,$C36:$C44,R36:R44) -> 1.5333469 | S35: =LOOKUP('Pool Energy Use Calculator'!$C$11,$C36:$C44,S36:S44) -> 2.1691248 | U35: =LOOKUP('Pool Energy Use Calculator'!$C$11,$C36:$C44,U36:U44) -> 0.0039559009 | V35: =LOOKUP('Pool Energy Use Calculator'!$C$11,$C36:$C44,V36:V44) -> 0.005231998 | W35: =LOOKUP('Pool Energy Use Calculator'!$C$11,$C36:$C44,W36:W44) -> 0.007401363
B36: cover | C36: 1 | E36: 12 | M36: =M54 -> 0.0034663105 | N36: =N54 -> 0.0048661666 | O36: =O54 -> 0.0066659817 | Q36: =Q54 -> 0.93808417 | R36: =R54 -> 1.3089547 | S36: =S54 -> 1.7889047 | U36: =Q36/293.071 -> 0.0032008768 | V36: =R36/293.071 -> 0.0044663397 | W36: =S36/293.071 -> 0.0061039976
B37: cover | C37: 2 | E37: 8 | M37: =M56 -> 0.0011998767 | N37: =N56 -> 0.0020997842 | O37: =O56 -> 0.0031996712 | Q37: =Q56 -> 0.2945148 | R37: =R56 -> 0.55630573 | S37: =S56 -> 0.81809666 | U37: =Q37/293.071 -> 0.0010049264 | V37: =R37/293.071 -> 0.0018981944 | W37: =S37/293.071 -> 0.0027914623
B38: cover | C38: 3A | D38: avg Dallas & Atlanta | E38: 7 | M38: =AVERAGE(M58,M60) -> 0.0035996301 | N38: =AVERAGE(N58,N60) -> 0.0050280547 | O38: =AVERAGE(O58,O60) -> 0.0071421232 | Q38: =AVERAGE(Q58,Q60) -> 0.91626826 | R38: =AVERAGE(R58,R60) -> 1.2902553 | S38: =AVERAGE(S58,S60) -> 1.8512359 | U38: =Q38/293.071 -> 0.0031264378 | V38: =R38/293.071 -> 0.0044025349 | W38: =S38/293.071 -> 0.0063166805
B39: cover | C39: 3B | E39: 6 | M39: =M60 -> 0.0045709588 | N39: =N60 -> 0.0060565205 | O39: =O60 -> 0.0084562739 | Q39: =Q60 -> 1.1593598 | R39: =R60 -> 1.5333469 | S39: =S60 -> 2.1691248 | U39: =Q39/293.071 -> 0.0039559009 | V39: =R39/293.071 -> 0.005231998 | W39: =S39/293.071 -> 0.007401363
B40: cover | C40: 3C | D40: use Los Angeles data - San Francisco is not typical | E40: 6 | M40: =M62 -> 0.0027997123 | N40: =N62 -> 0.0050661461 | O40: =O62 -> 0.0078658583 | Q40: =Q62 -> 0.74174097 | R40: =R62 -> 1.3525865 | S40: =S62 -> 2.0943274 | U40: =Q40/293.071 -> 0.0025309258 | V40: =R40/293.071 -> 0.0046152177 | W40: =S40/293.071 -> 0.0071461436
B41: cover | C41: 4 | D41: avg Kansas City, New York, Seattle | E41: 6 | M41: =AVERAGE(M66,M68,M70) -> 0.0063637905 | N41: =AVERAGE(N66,N68,N70) -> 0.0089946312 | O41: =AVERAGE(O66,O68,O70) -> 0.011821007 | Q41: =AVERAGE(Q66,Q68,Q70) -> 1.660918 | R41: =AVERAGE(R66,R68,R70) -> 2.3706623 | S41: =AVERAGE(S66,S68,S70) -> 3.1124033 | U41: =Q41/293.071 -> 0.0056672889 | V41: =R41/293.071 -> 0.0080890375 | W41: =S41/293.071 -> 0.010619963
B42: cover | C42: 5 | D42: avg Chicago, Denver, Boston | E42: 4 | M42: =AVERAGE(M72,M74,M76) -> 0.0043978814 | N42: =AVERAGE(N72,N74,N76) -> 0.0061060392 | O42: =AVERAGE(O72,O74,O76) -> 0.0084258008 | Q42: =AVERAGE(Q72,Q74,Q76) -> 1.1955119 | R42: =AVERAGE(R72,R74,R76) -> 1.6798251 | S42: =AVERAGE(S72,S74,S76) -> 2.3604816 | U42: =Q42/293.071 -> 0.004079257 | V42: =R42/293.071 -> 0.0057318027 | W42: =S42/293.071 -> 0.0080542993
B43: cover | C43: 6 | D43: avg CZ 5 and CZ 7 (no data) | E43: 4 | M43: =AVERAGE(M42,M44) -> 0.0045986941 | N43: =AVERAGE(N42,N44) -> 0.0061527011 | O43: =AVERAGE(O42,O44) -> 0.0090124072 | Q43: =AVERAGE(Q42,Q44) -> 1.2522333 | R43: =AVERAGE(R42,R44) -> 1.6580092 | S43: =AVERAGE(S42,S44) -> 2.4237477 | U43: =Q43/293.071 -> 0.0042727983 | V43: =R43/293.071 -> 0.0056573637 | W43: =S43/293.071 -> 0.0082701724
B44: cover | C44: 7 | E44: 4 | M44: =M78 -> 0.0047995068 | N44: =N78 -> 0.0061993629 | O44: =O78 -> 0.0095990136 | Q44: =Q78 -> 1.3089547 | R44: =R78 -> 1.6361933 | S44: =S78 -> 2.4870138 | U44: =Q44/293.071 -> 0.0044663397 | V44: =R44/293.071 -> 0.0055829247 | W44: =S44/293.071 -> 0.0084860455
B48: RAW DATA from DOE
F49: ENERGY COSTS | M49: GAS OR PROPANE | Q49: HEAT PUMP | U49: HEAT PUMP
E50: Months | G50: GAS OR PROPANE | J50: HEAT PUMP | M50: ENERGY USE | Q50: ENERGY USE | U50: ENERGY USE
B51: LOCATION | C51: CLIMATE ZONE | D51: SEASON | G51: TEMPERATURE | J51: TEMPERATURE | M51: (MBTU/sqft/month) @ 100% | Q51: (kWh/sqft/month) @ 1 COP | U51: (MBTU/sqft/month) @ 1 COP
F52: 78° | G52: 80° | H52: 82° | I52: 78° | J52: 80° | K52: 82° | M52: 78° | N52: 80° | O52: 82° | Q52: 78° | R52: 80° | S52: 82° | U52: 78° | V52: 80° | W52: 82°
B53: MIAMI | C53: 1A | D53: 1/1–12/31 | E53: 12 | F53: 2910.001 | G53: 3880.0013 | H53: 4904.496 | I53: 1498.596 | J53: 1989.0456 | K53: 2513.5542 | M53: =F53/1.09/1000*0.8/10/$E53 -> 0.017798171 | N53: =G53/1.09/1000*0.8/10/$E53 -> 0.023730895 | O53: =H53/1.09/1000*0.8/10/$E53 -> 0.029996917 | Q53: =I53/0.1301/1000*5/$E53 -> 4.7995004 | R53: =J53/0.1301/1000*5/$E53 -> 6.370246 | S53: =K53/0.1301/1000*5/$E53 -> 8.0500711 | U53: =Q53/293 -> 0.016380547 | V53: =R53/293 -> 0.021741454 | W53: =S53/293 -> 0.027474645
B54: W/COVER | C54: 1A W/COVER | D54: 1/1–12/31 | E54: 12 | F54: 566.74176 | G54: 795.61824 | H54: 1089.888 | I54: 292.9074 | J54: 408.708 | K54: 558.5676 | M54: =F54/1.09/1000*0.8/10/$E54 -> 0.0034663105 | N54: =G54/1.09/1000*0.8/10/$E54 -> 0.0048661666 | O54: =H54/1.09/1000*0.8/10/$E54 -> 0.0066659817 | Q54: =I54/0.1301/1000*5/$E54 -> 0.93808417 | R54: =J54/0.1301/1000*5/$E54 -> 1.3089547 | S54: =K54/0.1301/1000*5/$E54 -> 1.7889047 | U54: =Q54/293 -> 0.0032016524 | V54: =R54/293 -> 0.004467422 | W54: =S54/293 -> 0.0061054768
...
